Workbook

Sheet 전류·용량 계산표
A1: 대구텍 검사기 F2 #1 — 전류·용량 계산 및 차단기 선정 종합표
A2: ▶ 전체 부하 요약 (상단 자동계산)
A3: 구분 | B3: 총 정격전류 (A) | C3: 안전계수 ×1.25 | D3: 권장 차단기 (A) | E3: 총 부하 (kVA) | F3: 비고
A4: AC 3상 220V 파나소닉 A6 서보드라이버 | B4: =E82 -> 10950 | C4: =B4*1.25 -> 13687.5 | D4: → Sheet4 참조 | E4: → 하단 계산 | F4: → 하단 계산
A5: AC 단상 220V 파스텍 EziServo/EziSpeed | B5: =E99 -> 0 | C5: =B5*1.25 -> 0 | D5: → Sheet4 참조 | E5: → 하단 계산 | F5: → 하단 계산
A6: DC 24V I/O 모듈·센서·솔레노이드 등 | B6: =E107 -> 0 | C6: =B6*1.25 -> 0 | D6: → Sheet4 참조 | E6: → 하단 계산 | F6: → 하단 계산
A7: 기타 부하 HMI·조명·PC 등 | B7: =E114 -> 0 | C7: =B7*1.25 -> 0 | D7: → Sheet4 참조 | E7: → 하단 계산 | F7: → 하단 계산
A9: ▶ R/S/T 상별 전류 편중 분석
B10: R상 (A) | C10: S상 (A) | D10: T상 (A) | E10: 최대-최소 (A) | F10: 불균형률 (%) | G10: 판정 | H10: 기준: 불균형률 10% 이하 권장
A11: AC 3상 서보드라이버
A12: AC 3상 기타
A13: 전체 합계
A15: 판넬 | B15: 축/유닛명 | C15: 드라이버/장치 모델 | D15: 출력 (W) | E15: 정격전류 (A) | F15: 상수 | G15: R상 할당 | H15: S상 할당 | I15: T상 할당 | J15: 운전전류 (A) | K15: 전원 구분 (체크) | O15: 차단기 선정 (A) | P15: 제조사/ 모델 | Q15: 비고 / 수식 설명
K16: AC 3상 220V | L16: AC 단상 220V | M16: DC 24V | N16: 기타
A17: ■ 파나소닉 A6 서보드라이버 (AC 3상 220V) — 대구텍 F2 #1
A18: 판넬1 | B18: LO_Y1 | C18: MDDLN55BL | D18: 1000 | E18: =IFERROR(VLOOKUP(C18,파나소닉A6규격!$A:$C,3,FALSE),IFERROR(VLOOKUP(C18,파스텍EziServo규격!$A:$C,3,FALSE),"")) -> 1000 | F18: 3 | G18: 1 | H18: 1 | I18: 1 | J18: =IF(E18="","",E18*0.7) -> 700 | K18: ● | Q18: LO 로딩 Y축
A19: 판넬1 | B19: LO_X1 | C19: MCDLN35BL | D19: 750 | E19: =IFERROR(VLOOKUP(C19,파나소닉A6규격!$A:$C,3,FALSE),IFERROR(VLOOKUP(C19,파스텍EziServo규격!$A:$C,3,FALSE),"")) -> 750 | F19: 3 | G19: 1 | H19: 1 | I19: 1 | J19: =IF(E19="","",E19*0.7) -> 525 | K19: ● | Q19: LO 로딩 X축
A20: 판넬1 | B20: LO_Z1 | C20: MADLN05BE | D20: 50 | E20: =IFERROR(VLOOKUP(C20,파나소닉A6규격!$A:$C,3,FALSE),IFERROR(VLOOKUP(C20,파스텍EziServo규격!$A:$C,3,FALSE),"")) -> 50 | F20: 3 | G20: 1 | H20: 1 | I20: 1 | J20: =IF(E20="","",E20*0.7) -> 35 | K20: ● | Q20: LO 로딩 Z축
A21: 판넬1 | B21: ULO_Y1 | C21: MCDLN35BL | D21: 750 | E21: =IFERROR(VLOOKUP(C21,파나소닉A6규격!$A:$C,3,FALSE),IFERROR(VLOOKUP(C21,파스텍EziServo규격!$A:$C,3,FALSE),"")) -> 750 | F21: 3 | G21: 1 | H21: 1 | I21: 1 | J21: =IF(E21="","",E21*0.7) -> 525 | K21: ● | Q21: ULO 언로딩 Y축
A22: 판넬1 | B22: ULO_X1 | C22: MCDLN35BL | D22: 750 | E22: =IFERROR(VLOOKUP(C22,파나소닉A6규격!$A:$C,3,FALSE),IFERROR(VLOOKUP(C22,파스텍EziServo규격!$A:$C,3,FALSE),"")) -> 750 | F22: 3 | G22: 1 | H22: 1 | I22: 1 | J22: =IF(E22="","",E22*0.7) -> 525 | K22: ● | Q22: ULO 언로딩 X축
A23: 판넬1 | B23: ULO_Z1 | C23: MADLN05BE | D23: 50 | E23: =IFERROR(VLOOKUP(C23,파나소닉A6규격!$A:$C,3,FALSE),IFERROR(VLOOKUP(C23,파스텍EziServo규격!$A:$C,3,FALSE),"")) -> 50 | F23: 3 | G23: 1 | H23: 1 | I23: 1 | J23: =IF(E23="","",E23*0.7) -> 35 | K23: ● | Q23: ULO 언로딩 Z축
A24: 판넬1 | B24: NG_EV | C24: MCDLN35BE | D24: 750 | E24: =IFERROR(VLOOKUP(C24,파나소닉A6규격!$A:$C,3,FALSE),IFERROR(VLOOKUP(C24,파스텍EziServo규격!$A:$C,3,FALSE),"")) -> 750 | F24: 3 | G24: 1 | H24: 1 | I24: 1 | J24: =IF(E24="","",E24*0.7) -> 525 | K24: ● | Q24: NG 이젝터 (Brake 내장)
A25: 판넬1 | B25: NG_FD | C25: MADLN05BE | D25: 50 | E25: =IFERROR(VLOOKUP(C25,파나소닉A6규격!$A:$C,3,FALSE),IFERROR(VLOOKUP(C25,파스텍EziServo규격!$A:$C,3,FALSE),"")) -> 50 | F25: 3 | G25: 1 | H25: 1 | I25: 1 | J25: =IF(E25="","",E25*0.7) -> 35 | K25: ● | Q25: NG 피더
A26: 판넬1 | B26: NG_FD_Z | C26: MBDLN25BE | D26: 400 | E26: =IFERROR(VLOOKUP(C26,파나소닉A6규격!$A:$C,3,FALSE),IFERROR(VLOOKUP(C26,파스텍EziServo규격!$A:$C,3,FALSE),"")) -> 400 | F26: 3 | G26: 1 | H26: 1 | I26: 1 | J26: =IF(E26="","",E26*0.7) -> 280 | K26: ● | Q26: NG 피더 Z축
A27: 판넬1 | B27: NG_FD_ALIGN | C27: MADLN05BE | D27: 50 | E27: =IFERROR(VLOOKUP(C27,파나소닉A6규격!$A:$C,3,FALSE),IFERROR(VLOOKUP(C27,파스텍EziServo규격!$A:$C,3,FALSE),"")) -> 50 | F27: 3 | G27: 1 | H27: 1 | I27: 1 | J27: =IF(E27="","",E27*0.7) -> 35 | K27: ● | Q27: NG 정렬
A28: 판넬1 | B28: NG_FD_INDEX | C28: MBDLN25BE | D28: 400 | E28: =IFERROR(VLOOKUP(C28,파나소닉A6규격!$A:$C,3,FALSE),IFERROR(VLOOKUP(C28,파스텍EziServo규격!$A:$C,3,FALSE),"")) -> 400 | F28: 3 | G28: 1 | H28: 1 | I28: 1 | J28: =IF(E28="","",E28*0.7) -> 280 | K28: ● | Q28: NG 인덱스
A29: 판넬1 | B29: JIG_ULO_Y | C29: MADLN05BE | D29: 50 | E29: =IFERROR(VLOOKUP(C29,파나소닉A6규격!$A:$C,3,FALSE),IFERROR(VLOOKUP(C29,파스텍EziServo규격!$A:$C,3,FALSE),"")) -> 50 | F29: 3 | G29: 1 | H29: 1 | I29: 1 | J29: =IF(E29="","",E29*0.7) -> 35 | K29: ● | Q29: JIG 언로딩 Y
A30: 판넬1 | B30: JIG_ULO_Z | C30: MADLN05BE | D30: 50 | E30: =IFERROR(VLOOKUP(C30,파나소닉A6규격!$A:$C,3,FALSE),IFERROR(VLOOKUP(C30,파스텍EziServo규격!$A:$C,3,FALSE),"")) -> 50 | F30: 3 | G30: 1 | H30: 1 | I30: 1 | J30: =IF(E30="","",E30*0.7) -> 35 | K30: ● | Q30: JIG 언로딩 Z
A31: 판넬2 | B31: GOOD_EV | C31: MCDLN35BE | D31: 750 | E31: =IFERROR(VLOOKUP(C31,파나소닉A6규격!$A:$C,3,FALSE),IFERROR(VLOOKUP(C31,파스텍EziServo규격!$A:$C,3,FALSE),"")) -> 750 | F31: 3 | G31: 1 | H31: 1 | I31: 1 | J31: =IF(E31="","",E31*0.7) -> 525 | K31: ● | Q31: GOOD 이젝터
A32: 판넬2 | B32: GOOD_FD | C32: MADLN05BE | D32: 50 | E32: =IFERROR(VLOOKUP(C32,파나소닉A6규격!$A:$C,3,FALSE),IFERROR(VLOOKUP(C32,파스텍EziServo규격!$A:$C,3,FALSE),"")) -> 50 | F32: 3 | G32: 1 | H32: 1 | I32: 1 | J32: =IF(E32="","",E32*0.7) -> 35 | K32: ● | Q32: GOOD 피더
A33: 판넬2 | B33: GOOD_FD_Z | C33: MBDLN25BE | D33: 400 | E33: =IFERROR(VLOOKUP(C33,파나소닉A6규격!$A:$C,3,FALSE),IFERROR(VLOOKUP(C33,파스텍EziServo규격!$A:$C,3,FALSE),"")) -> 400 | F33: 3 | G33: 1 | H33: 1 | I33: 1 | J33: =IF(E33="","",E33*0.7) -> 280 | K33: ● | Q33: GOOD 피더 Z축
A34: 판넬2 | B34: GOOD_FD_ALIGN | C34: MADLN05BE | D34: 50 | E34: =IFERROR(VLOOKUP(C34,파나소닉A6규격!$A:$C,3,FALSE),IFERROR(VLOOKUP(C34,파스텍EziServo규격!$A:$C,3,FALSE),"")) -> 50 | F34: 3 | G34: 1 | H34: 1 | I34: 1 | J34: =IF(E34="","",E34*0.7) -> 35 | K34: ● | Q34: GOOD 정렬
A35: 판넬2 | B35: GOOD_FD_INDEX | C35: MBDLN25BE | D35: 400 | E35: =IFERROR(VLOOKUP(C35,파나소닉A6규격!$A:$C,3,FALSE),IFERROR(VLOOKUP(C35,파스텍EziServo규격!$A:$C,3,FALSE),"")) -> 400 | F35: 3 | G35: 1 | H35: 1 | I35: 1 | J35: =IF(E35="","",E35*0.7) -> 280 | K35: ● | Q35: GOOD 인덱스
A36: 판넬2 | B36: TURN_Y | C36: MBDLN25BE | D36: 400 | E36: =IFERROR(VLOOKUP(C36,파나소닉A6규격!$A:$C,3,FALSE),IFERROR(VLOOKUP(C36,파스텍EziServo규격!$A:$C,3,FALSE),"")) -> 400 | F36: 3 | G36: 1 | H36: 1 | I36: 1 | J36: =IF(E36="","",E36*0.7) -> 280 | K36: ● | Q36: 턴테이블 Y
A37: 판넬2 | B37: TURN_GRIPPER_Y1 | C37: MADLN15BE | D37: 200 | E37: =IFERROR(VLOOKUP(C37,파나소닉A6규격!$A:$C,3,FALSE),IFERROR(VLOOKUP(C37,파스텍EziServo규격!$A:$C,3,FALSE),"")) -> 200 | F37: 3 | G37: 1 | H37: 1 | I37: 1 | J37: =IF(E37="","",E37*0.7) -> 140 | K37: ● | Q37: 그리퍼1 Y
A38: 판넬2 | B38: TURN_GRIPPER_X1 | C38: MADLN05BE | D38: 50 | E38: =IFERROR(VLOOKUP(C38,파나소닉A6규격!$A:$C,3,FALSE),IFERROR(VLOOKUP(C38,파스텍EziServo규격!$A:$C,3,FALSE),"")) -> 50 | F38: 3 | G38: 1 | H38: 1 | I38: 1 | J38: =IF(E38="","",E38*0.7) -> 35 | K38: ● | Q38: 그리퍼1 X ← 모델 확인 필요
A39: 판넬2 | B39: TURN_GRIPPER_Z1 | C39: MADLN05BE | D39: 50 | E39: =IFERROR(VLOOKUP(C39,파나소닉A6규격!$A:$C,3,FALSE),IFERROR(VLOOKUP(C39,파스텍EziServo규격!$A:$C,3,FALSE),"")) -> 50 | F39: 3 | G39: 1 | H39: 1 | I39: 1 | J39: =IF(E39="","",E39*0.7) -> 35 | K39: ● | Q39: 그리퍼1 Z ← 모델 확인 필요
A40: 판넬2 | B40: TURN_GRIPPER_Y2 | C40: MADLN15BE | D40: 200 | E40: =IFERROR(VLOOKUP(C40,파나소닉A6규격!$A:$C,3,FALSE),IFERROR(VLOOKUP(C40,파스텍EziServo규격!$A:$C,3,FALSE),"")) -> 200 | F40: 3 | G40: 1 | H40: 1 | I40: 1 | J40: =IF(E40="","",E40*0.7) -> 140 | K40: ● | Q40: 그리퍼2 Y
A41: 판넬2 | B41: TURN_GRIPPER_X2 | C41: MADLN05BE | D41: 50 | E41: =IFERROR(VLOOKUP(C41,파나소닉A6규격!$A:$C,3,FALSE),IFERROR(VLOOKUP(C41,파스텍EziServo규격!$A:$C,3,FALSE),"")) -> 50 | F41: 3 | G41: 1 | H41: 1 | I41: 1 | J41: =IF(E41="","",E41*0.7) -> 35 | K41: ● | Q41: 그리퍼2 X ← 모델 확인 필요
A42: 판넬2 | B42: TURN_GRIPPER_Z2 | C42: MADLN05BE | D42: 50 | E42: =IFERROR(VLOOKUP(C42,파나소닉A6규격!$A:$C,3,FALSE),IFERROR(VLOOKUP(C42,파스텍EziServo규격!$A:$C,3,FALSE),"")) -> 50 | F42: 3 | G42: 1 | H42: 1 | I42: 1 | J42: =IF(E42="","",E42*0.7) -> 35 | K42: ● | Q42: 그리퍼2 Z ← 모델 확인 필요
...

Sheet 파나소닉A6규격
A1: 파나소닉 A6 서보드라이버 규격표 (MINAS A6 Series)
A2: 드라이버 모델 | B2: 대응 모터 | C2: 정격출력(W) | D2: 전원 | E2: 정격입력전류(A) | F2: 최대입력전류(A) | G2: 제어방식 | H2: 통신 | I2: 특이사항 | J2: 비고
A3: MADLN05BE | B3: MSMF/MQMF 50W | C3: 50 | D3: AC3상 200V | E3: 0.3 | F3: 0.8 | G3: フルクロ | H3: EtherCAT/Modbus | I3: 소형 단축용
A4: MADLN10BE | B4: MSMF/MQMF 100W | C4: 100 | D4: AC3상 200V | E4: 0.5 | F4: 1.2 | G4: フルクロ | H4: EtherCAT/Modbus
A5: MADLN15BE | B5: MSMF/MQMF 200W | C5: 200 | D5: AC3상 200V | E5: 1 | F5: 2.4 | G5: フルクロ | H5: EtherCAT/Modbus
A6: MBDLN25BE | B6: MSMF/MQMF 400W | C6: 400 | D6: AC3상 200V | E6: 1.5 | F6: 4 | G6: フルクロ | H6: EtherCAT/Modbus
A7: MCDLN35BL | B7: MSMF/MQMF 750W | C7: 750 | D7: AC3상 200V | E7: 2.4 | F7: 7 | G7: フルクロ | H7: EtherCAT/Modbus | I7: 중형 축용
A8: MCDLN35BE | B8: MSMF/MQMF 750W | C8: 750 | D8: AC3상 200V | E8: 2.4 | F8: 7 | G8: フルクロ | H8: EtherCAT/Modbus | I8: Brake 내장형
A9: MDDLN55BL | B9: MSMF 1kW | C9: 1000 | D9: AC3상 200V | E9: 3.4 | F9: 10 | G9: フルクロ | H9: EtherCAT/Modbus | I9: 대형 주축용
A10: MDDLN85BL | B10: MSMF 1.5kW | C10: 1500 | D10: AC3상 200V | E10: 5.5 | F10: 15 | G10: フルクロ | H10: EtherCAT/Modbus
A11: MEDLN15BL | B11: MSMF 2kW | C11: 2000 | D11: AC3상 200V | E11: 7.5 | F11: 20 | G11: フルクロ | H11: EtherCAT/Modbus
A12: MFDLN23BL | B12: MSMF 3kW | C12: 3000 | D12: AC3상 200V | E12: 11 | F12: 30 | G12: フルクロ | H12: EtherCAT/Modbus | I12: 고출력
A14: ※ 정격입력전류: I = P_출력(VA) ÷ (√3 × V_입력 × PF) | 안전계수 1.25 적용 후 차단기 선정 | 출처: Panasonic MINAS A6 Catalog

Sheet 파스텍EziServo규격
A1: 파스텍(Fastech) 스텝드라이버 규격표
A2: 드라이버 모델 | B2: 입력전원 | C2: 출력전류 max(A) | D2: 마이크로스텝 | E2: 통신/제어 | F2: 보호기능 | G2: 대응 모터 | H2: 특이사항 | I2: 비고
A3: EM542S | B3: DC 20~50V | C3: 4.2 | D3: 1~256 | E3: 스텝/방향, CW/CCW | F3: 과열/과전류/위상오류 | G3: 2상 스텝모터 | H3: 소형 범용
A4: EM806 | B4: DC 24~80V | C4: 8 | D4: 1~256 | E4: 스텝/방향, CW/CCW | F4: 과열/과전류 | G4: 2상 스텝모터 | H4: 고토크 대형
A5: EZB2-EC | B5: DC 24~48V | C5: 2 | D5: 1~256 | E5: EtherCAT | F5: 과열/과전류 | G5: 2상 스텝모터 | H5: 네트워크 제어
A6: EZB2-ML | B6: DC 24~48V | C6: 2 | D6: 1~256 | E6: MECHATROLINK-III | F6: 과열/과전류 | G6: 2상 스텝모터 | H6: ML3 네트워크
A7: EZS2-EC | B7: DC 24~48V | C7: 4 | D7: 1~256 | E7: EtherCAT | F7: 과열/과전류 | G7: 2상 스텝모터 | H7: 중형 EtherCAT
A8: EziSERVO-EC | B8: AC 100~240V | C8: 3 | D8: - | E8: EtherCAT (CiA 402) | F8: 과열/과전류/위치오류 | G8: 폐루프 스텝 | H8: 폐루프(엔코더 내장)
A10: ※ 파스텍 DC 드라이버 전원: 별도 SMPS 필요 (DC 전원장치 용량 = 합계전류×1.25 이상) | 출처: Fastech 제품 카탈로그

Sheet 차단기 규격 참조표
A1: 차단기 규격 참조표 (MCCB / MCB — AC 220V 3상/단상)
A2: 정격전류(A) | B2: 적용 부하전류 범위 | C2: 제조사 | D2: 모델 3P (MCCB) | E2: 모델 1P (MCB) | F2: 특이사항 | G2: 비고
A3: 3 | B3: ~2.4A | C3: LS/Chint | D3: ABN3c / NXB-63 | E3: BKN1-1P C3 | F3: 조명·소형제어
A4: 5 | B4: 2.4~4A | C4: LS/Chint | D4: ABN5c / NXB-63 | E4: BKN1-1P C5 | F4: 소형I/O
A5: 10 | B5: 4~8A | C5: LS/Chint | D5: ABN10c / NXB-63 | E5: BKN1-1P C10 | F5: 소형서보 1~2축
A6: 15 | B6: 8~12A | C6: LS/Chint | D6: ABN15c / NXB-63 | E6: BKN1-1P C15
A7: 20 | B7: 12~16A | C7: LS/Chint | D7: ABN20c / NXB-63 | E7: BKN1-1P C20 | F7: 중형서보
A8: 25 | B8: 16~20A | C8: LS/Chint | D8: ABN25c / NXB-63 | E8: BKN1-1P C25
A9: 30 | B9: 20~24A | C9: LS/Chint | D9: ABN30c / NXB-63 | E9: - | F9: 다축서보 판넬
A10: 40 | B10: 24~32A | C10: LS/Chint | D10: ABN40c | E10: -
A11: 50 | B11: 32~40A | C11: LS/Chint | D11: ABN50c | E11: -
A12: 63 | B12: 40~50A | C12: LS/Chint | D12: ABN63c | E12: - | F12: 대형 판넬
A13: 75 | B13: 50~60A | C13: LS/Chint | D13: ABN75c | E13: - | F13: 메인 차단기
A14: 100 | B14: 60~80A | C14: LS/Chint | D14: ABN100c | E14: -
A15: 125 | B15: 80~100A | C15: LS | D15: ABN125c | E15: - | F15: 대형 메인
