Workbook

Sheet 판넬별 차단기 선정표
A1: 대구텍 검사기 F2 #1 — 판넬별 전류·용량 계산 및 차단기 선정표
A2: 전원: | B2: AC 220V / 3상 | C2: 역률(PF): | D2: 0.95 | E2: 안전계수: | F2: 1.25 | G2: 수용률: | H2: 0.5 | I2: 작성일: | J2: 2026-04-03
A4: 구분 | B4: 총 정격전류 (A) | C4: 안전계수 ×1.25 | D4: 권장 차단기 (A) | E4: 총 부하 (kVA) | F4: 비고
A5: AC 3상 220V 파나소닉 A6 서보드라이버 | B5: =E108 -> 0.3 | C5: =B5*1.25 -> 0.375 | D5: → Sheet4 참조 | E5: → 하단 계산 | F5: → 하단 계산
A6: AC 단상 220V 파스텍 EziServo/EziSpeed | B6: =E125 -> 9 | C6: =B6*1.25 -> 11.25 | D6: → Sheet4 참조 | E6: → 하단 계산 | F6: → 하단 계산
A7: DC 24V I/O 모듈·센서·솔레노이드 등 | B7: =E133 -> 1 | C7: =B7*1.25 -> 1.25 | D7: → Sheet4 참조 | E7: → 하단 계산 | F7: → 하단 계산
A8: 기타 부하 HMI·조명·PC 등 | B8: =E140 -> 0 | C8: =B8*1.25 -> 0 | D8: → Sheet4 참조 | E8: → 하단 계산 | F8: → 하단 계산
B10: R상 (A) | C10: S상 (A) | D10: T상 (A) | E10: 최대-최소 (A) | F10: 불균형률 (%) | G10: 판정 | H10: 기준: 불균형률 10% 이하 권장
A11: AC 3상 서보드라이버
A12: AC 3상 기타
A13: 전체 합계
A15: 전원: | B15: AC 220V / 3상 | C15: 역률(PF): | D15: 0.85 | E15: 안전계수: | F15: 1.25 | G15: 수용률: | H15: 0.5 | I15: 작성일: | J15: 2026-04-03
A16: 판넬 | B16: 축/유닛명 | C16: 드라이버/장치 모델 | D16: 출력 (W) | E16: 정격전류 (A) | F16: 상수 | G16: R상 할당 | H16: S상 할당 | I16: T상 할당 | J16: 설계전류 (A) | K16: 전원 구분 | O16: 권장 차단기(A) | P16: 제조사/모델 | Q16: 비고
K17: AC 3상 220V | L17: AC 단상 220V | M17: DC 24V | N17: 기타
A18: ■ 판넬 1 — AC 3상 서보드라이버 (파나소닉 A6)
A19: 판넬1 | B19: LO_Y1 | C19: MDDLN55BL | D19: 1000 | E19: =IFERROR(VLOOKUP(C19,파나소닉A6규격!$A:$C,3,FALSE),IFERROR(VLOOKUP(C19,파스텍EziServo규격!$A:$C,3,FALSE),"")) -> 3.4 | F19: 1 | G19: 1 | H19: 1 | I19: 1 | J19: =IF(E19="","",ROUND(E19*0.7,3)) -> 2.38 | K19: ●
A20: 판넬1 | B20: LO_X1 | C20: MCDLN35BL | D20: 750 | E20: =IFERROR(VLOOKUP(C20,파나소닉A6규격!$A:$C,3,FALSE),IFERROR(VLOOKUP(C20,파스텍EziServo규격!$A:$C,3,FALSE),"")) -> 2.4 | F20: 1 | G20: 1 | H20: 1 | I20: 1 | J20: =IF(E20="","",ROUND(E20*0.7,3)) -> 1.68 | K20: ●
A21: 판넬1 | B21: LO_Z1 | C21: MADLN05BE | D21: 50 | E21: =IFERROR(VLOOKUP(C21,파나소닉A6규격!$A:$C,3,FALSE),IFERROR(VLOOKUP(C21,파스텍EziServo규격!$A:$C,3,FALSE),"")) -> 0.3 | F21: 1 | G21: 1 | H21: 1 | I21: 1 | J21: =IF(E21="","",ROUND(E21*0.7,3)) -> 0.21 | K21: ●
A22: 판넬1 | B22: ULO_Y1 | C22: MCDLN35BL | D22: 750 | E22: =IFERROR(VLOOKUP(C22,파나소닉A6규격!$A:$C,3,FALSE),IFERROR(VLOOKUP(C22,파스텍EziServo규격!$A:$C,3,FALSE),"")) -> 2.4 | F22: 1 | G22: 1 | H22: 1 | I22: 1 | J22: =IF(E22="","",ROUND(E22*0.7,3)) -> 1.68 | K22: ●
A23: 판넬1 | B23: ULO_X1 | C23: MCDLN35BL | D23: 750 | E23: =IFERROR(VLOOKUP(C23,파나소닉A6규격!$A:$C,3,FALSE),IFERROR(VLOOKUP(C23,파스텍EziServo규격!$A:$C,3,FALSE),"")) -> 2.4 | F23: 1 | G23: 1 | H23: 1 | I23: 1 | J23: =IF(E23="","",ROUND(E23*0.7,3)) -> 1.68 | K23: ●
A24: 판넬1 | B24: ULO_Z1 | C24: MADLN05BE | D24: 50 | E24: =IFERROR(VLOOKUP(C24,파나소닉A6규격!$A:$C,3,FALSE),IFERROR(VLOOKUP(C24,파스텍EziServo규격!$A:$C,3,FALSE),"")) -> 0.3 | F24: 1 | G24: 1 | H24: 1 | I24: 1 | J24: =IF(E24="","",ROUND(E24*0.7,3)) -> 0.21 | K24: ●
A25: 판넬1 | B25: NG_EV | C25: MCDLN35BE | D25: 750 | E25: =IFERROR(VLOOKUP(C25,파나소닉A6규격!$A:$C,3,FALSE),IFERROR(VLOOKUP(C25,파스텍EziServo규격!$A:$C,3,FALSE),"")) -> 2.4 | F25: 1 | G25: 1 | H25: 1 | I25: 1 | J25: =IF(E25="","",ROUND(E25*0.7,3)) -> 1.68 | K25: ●
A26: 판넬1 | B26: NG_FD | C26: MADLN05BE | D26: 50 | E26: =IFERROR(VLOOKUP(C26,파나소닉A6규격!$A:$C,3,FALSE),IFERROR(VLOOKUP(C26,파스텍EziServo규격!$A:$C,3,FALSE),"")) -> 0.3 | F26: 1 | G26: 1 | H26: 1 | I26: 1 | J26: =IF(E26="","",ROUND(E26*0.7,3)) -> 0.21 | K26: ●
A27: 판넬1 | B27: NG_FD_Z | C27: MBDLN25BE | D27: 400 | E27: =IFERROR(VLOOKUP(C27,파나소닉A6규격!$A:$C,3,FALSE),IFERROR(VLOOKUP(C27,파스텍EziServo규격!$A:$C,3,FALSE),"")) -> 1.5 | F27: 1 | G27: 1 | H27: 1 | I27: 1 | J27: =IF(E27="","",ROUND(E27*0.7,3)) -> 1.05 | K27: ●
A28: 판넬1 | B28: NG_FD_ALIGN | C28: MADLN05BE | D28: 50 | E28: =IFERROR(VLOOKUP(C28,파나소닉A6규격!$A:$C,3,FALSE),IFERROR(VLOOKUP(C28,파스텍EziServo규격!$A:$C,3,FALSE),"")) -> 0.3 | F28: 1 | G28: 1 | H28: 1 | I28: 1 | J28: =IF(E28="","",ROUND(E28*0.7,3)) -> 0.21 | K28: ●
A29: 판넬1 | B29: NG_FD_INDEX | C29: MBDLN25BE | D29: 400 | E29: =IFERROR(VLOOKUP(C29,파나소닉A6규격!$A:$C,3,FALSE),IFERROR(VLOOKUP(C29,파스텍EziServo규격!$A:$C,3,FALSE),"")) -> 1.5 | F29: 1 | G29: 1 | H29: 1 | I29: 1 | J29: =IF(E29="","",ROUND(E29*0.7,3)) -> 1.05 | K29: ●
A30: 판넬1 | B30: JIG_ULO_Y | C30: MADLN05BE | D30: 50 | E30: =IFERROR(VLOOKUP(C30,파나소닉A6규격!$A:$C,3,FALSE),IFERROR(VLOOKUP(C30,파스텍EziServo규격!$A:$C,3,FALSE),"")) -> 0.3 | F30: 1 | G30: 1 | H30: 1 | I30: 1 | J30: =IF(E30="","",ROUND(E30*0.7,3)) -> 0.21 | K30: ●
A31: 판넬1 | B31: JIG_ULO_Z | C31: MADLN05BE | D31: 50 | E31: =IFERROR(VLOOKUP(C31,파나소닉A6규격!$A:$C,3,FALSE),IFERROR(VLOOKUP(C31,파스텍EziServo규격!$A:$C,3,FALSE),"")) -> 0.3 | F31: 1 | G31: 1 | H31: 1 | I31: 1 | J31: =IF(E31="","",ROUND(E31*0.7,3)) -> 0.21 | K31: ●
A32: ▶ 판넬 1 AC합계 | E32: =SUM(E19:E31) -> 17.8 | J32: =SUM(J19:J31) -> 12.46 | O32: 20 | P32: LS ABN20c | Q32: =J32&"A×1.25="&TEXT(J32*1.25,"0.00")&"A → 20A 선정" -> 12.46A×1.25=15.58A → 20A 선정
A33: 판넬 | B33: 축/유닛명 | C33: 드라이버/장치 모델 | D33: 출력 (W) | E33: 정격전류 (A) | F33: 상수 | G33: R상 할당 | H33: S상 할당 | I33: T상 할당 | J33: 설계전류 (A) | K33: 전원 구분 | O33: 권장 차단기(A) | P33: 제조사/모델 | Q33: 비고
K34: AC 3상 220V | L34: AC 단상 220V | M34: DC 24V | N34: 기타
A35: ■ 파스텍 EziServo / EziSpeed (AC 단상 or DC 입력) — 대구텍 F2 #1
A36: 판넬1 | B36: LO_R1_1 | C36: Ezi-EC-42XL-A | D36: 0 | E36: =IFERROR(VLOOKUP(C36,[1]파나소닉A6규격!$A:$C,3,FALSE),IFERROR(VLOOKUP(C36,[1]파스텍EziServo규격!$A:$C,3,FALSE),"")) | F36: 1 | G36: 0 | H36: 0 | I36: 0 | J36: =IF(E36="","",E36*0.7) | L36: ● | Q36: LO 회전 R1 #1
A37: 판넬1 | B37: LO_R1_2 | C37: Ezi-EC-42XL-A | D37: 0 | E37: =IFERROR(VLOOKUP(C37,[1]파나소닉A6규격!$A:$C,3,FALSE),IFERROR(VLOOKUP(C37,[1]파스텍EziServo규격!$A:$C,3,FALSE),"")) | F37: 1 | G37: 0 | H37: 0 | I37: 0 | J37: =IF(E37="","",E37*0.7) | L37: ● | Q37: LO 회전 R1 #2
A39: 판넬 | B39: 축/유닛명 | C39: 드라이버/장치 모델 | D39: 출력 (W) | E39: 정격전류 (A) | F39: 상수 | G39: R상 할당 | H39: S상 할당 | I39: T상 할당 | J39: 설계전류 (A) | K39: 전원 구분 | O39: 권장 차단기(A) | P39: 제조사/모델 | Q39: 비고
K40: AC 3상 220V | L40: AC 단상 220V | M40: DC 24V | N40: 기타
A41: ■ 판넬 2 — AC 3상 서보드라이버 (파나소닉 A6)
A42: 판넬2 | B42: GOOD_EV | C42: MCDLN35BE | D42: 750 | E42: =IFERROR(VLOOKUP(C42,파나소닉A6규격!$A:$C,3,FALSE),IFERROR(VLOOKUP(C42,파스텍EziServo규격!$A:$C,3,FALSE),"")) -> 2.4 | F42: 1 | G42: 1 | H42: 1 | I42: 1 | J42: =IF(E42="","",ROUND(E42*0.7,3)) -> 1.68 | K42: ●
A43: 판넬2 | B43: GOOD_FD | C43: MADLN05BE | D43: 50 | E43: =IFERROR(VLOOKUP(C43,파나소닉A6규격!$A:$C,3,FALSE),IFERROR(VLOOKUP(C43,파스텍EziServo규격!$A:$C,3,FALSE),"")) -> 0.3 | F43: 1 | G43: 1 | H43: 1 | I43: 1 | J43: =IF(E43="","",ROUND(E43*0.7,3)) -> 0.21 | K43: ●
A44: 판넬2 | B44: GOOD_FD_Z | C44: MBDLN25BE | D44: 400 | E44: =IFERROR(VLOOKUP(C44,파나소닉A6규격!$A:$C,3,FALSE),IFERROR(VLOOKUP(C44,파스텍EziServo규격!$A:$C,3,FALSE),"")) -> 1.5 | F44: 1 | G44: 1 | H44: 1 | I44: 1 | J44: =IF(E44="","",ROUND(E44*0.7,3)) -> 1.05 | K44: ●
...

Sheet 파나소닉A6규격
A1: 파나소닉 A6 서보드라이버 정격입력전류 (카탈로그 기준, 3상 AC200V)
A2: 드라이버 모델 | B2: 정격출력 (W) | C2: 정격입력전류 (A) | D2: 비고
A3: MADLN05BE | B3: 50 | C3: 0.3 | D3: 50W 서보드라이버
A4: MADLN10BE | B4: 100 | C4: 0.5 | D4: 100W 서보드라이버
A5: MADLN15BE | B5: 200 | C5: 1 | D5: 200W 서보드라이버
A6: MBDLN25BE | B6: 400 | C6: 1.5 | D6: 400W 서보드라이버
A7: MCDLN35BL | B7: 750 | C7: 2.4 | D7: 750W 서보드라이버 (BL)
A8: MCDLN35BE | B8: 750 | C8: 2.4 | D8: 750W 서보드라이버 (BE)
A9: MDDLN55BL | B9: 1000 | C9: 3.4 | D9: 1kW 서보드라이버 (BL)
A10: MDDLN55BE | B10: 1000 | C10: 3.4 | D10: 1kW 서보드라이버 (BE)
A11: MDDLN85BL | B11: 1500 | C11: 5.5 | D11: 1.5kW 서보드라이버 (BL)
A13: ※ A열 모델명과 메인시트 C열 코드 정확히 일치 필요 | 카탈로그 정격입력전류 기준 | 모델 추가 시 이 시트에 행 추가
A15: 파나소닉 A6 서보드라이버 규격표 (MINAS A6 Series)
A16: 드라이버 모델 | B16: 대응 모터 | C16: 정격출력(W) | D16: 전원 | E16: 정격입력전류(A) | F16: 최대입력전류(A) | G16: 제어방식 | H16: 통신 | I16: 특이사항 | J16: 비고
A17: MADLN05BE | B17: MSMF/MQMF 50W | C17: 50 | D17: AC3상 200V | E17: 0.3 | F17: 0.8 | G17: フルクロ | H17: EtherCAT/Modbus | I17: 소형 단축용
A18: MADLN10BE | B18: MSMF/MQMF 100W | C18: 100 | D18: AC3상 200V | E18: 0.5 | F18: 1.2 | G18: フルクロ | H18: EtherCAT/Modbus
A19: MADLN15BE | B19: MSMF/MQMF 200W | C19: 200 | D19: AC3상 200V | E19: 1 | F19: 2.4 | G19: フルクロ | H19: EtherCAT/Modbus
A20: MBDLN25BE | B20: MSMF/MQMF 400W | C20: 400 | D20: AC3상 200V | E20: 1.5 | F20: 4 | G20: フルクロ | H20: EtherCAT/Modbus
A21: MCDLN35BL | B21: MSMF/MQMF 750W | C21: 750 | D21: AC3상 200V | E21: 2.4 | F21: 7 | G21: フルクロ | H21: EtherCAT/Modbus | I21: 중형 축용
A22: MCDLN35BE | B22: MSMF/MQMF 750W | C22: 750 | D22: AC3상 200V | E22: 2.4 | F22: 7 | G22: フルクロ | H22: EtherCAT/Modbus | I22: Brake 내장형
A23: MDDLN55BL | B23: MSMF 1kW | C23: 1000 | D23: AC3상 200V | E23: 3.4 | F23: 10 | G23: フルクロ | H23: EtherCAT/Modbus | I23: 대형 주축용
A24: MDDLN85BL | B24: MSMF 1.5kW | C24: 1500 | D24: AC3상 200V | E24: 5.5 | F24: 15 | G24: フルクロ | H24: EtherCAT/Modbus
A25: MEDLN15BL | B25: MSMF 2kW | C25: 2000 | D25: AC3상 200V | E25: 7.5 | F25: 20 | G25: フルクロ | H25: EtherCAT/Modbus
A26: MFDLN23BL | B26: MSMF 3kW | C26: 3000 | D26: AC3상 200V | E26: 11 | F26: 30 | G26: フルクロ | H26: EtherCAT/Modbus | I26: 고출력
A28: ※ 정격입력전류: I = P_출력(VA) ÷ (√3 × V_입력 × PF) | 안전계수 1.25 적용 후 차단기 선정 | 출처: Panasonic MINAS A6 Catalog

Sheet 파스텍EziServo규격
A1: 파스텍 EZS2/EziServo 정격전류 (VLOOKUP 소스)
A2: 드라이버 모델 | B2: 정격전류 (A) | C2: 비고
A3: EZS2-EC-42M | B3: 1.2 | C3: DC 24V 입력 스텝서보
A4: EZS2-EC-42XL | B4: 1.2 | C4: DC 24V 입력 스텝서보 (XL)
A5: Ezi-EC-42M-A | B5: 1.5 | C5: AC 입력 스텝서보
A6: Ezi-EC-42XL-A | B6: 2 | C6: AC 입력 스텝서보 (XL)
A7: EZI-SPEED60H30CR100P | B7: 1 | C7: DC 24V 입력 스텝모터드라이버
A9: 파스텍(Fastech) 스텝드라이버 규격표
A10: 드라이버 모델 | B10: 입력전원 | C10: 출력전류 max(A) | D10: 마이크로스텝 | E10: 통신/제어 | F10: 보호기능 | G10: 대응 모터 | H10: 특이사항 | I10: 비고
A11: EM542S | B11: DC 20~50V | C11: 4.2 | D11: 1~256 | E11: 스텝/방향, CW/CCW | F11: 과열/과전류/위상오류 | G11: 2상 스텝모터 | H11: 소형 범용
A12: EM806 | B12: DC 24~80V | C12: 8 | D12: 1~256 | E12: 스텝/방향, CW/CCW | F12: 과열/과전류 | G12: 2상 스텝모터 | H12: 고토크 대형
A13: EZB2-EC | B13: DC 24~48V | C13: 2 | D13: 1~256 | E13: EtherCAT | F13: 과열/과전류 | G13: 2상 스텝모터 | H13: 네트워크 제어
A14: EZB2-ML | B14: DC 24~48V | C14: 2 | D14: 1~256 | E14: MECHATROLINK-III | F14: 과열/과전류 | G14: 2상 스텝모터 | H14: ML3 네트워크
A15: EZS2-EC | B15: DC 24~48V | C15: 4 | D15: 1~256 | E15: EtherCAT | F15: 과열/과전류 | G15: 2상 스텝모터 | H15: 중형 EtherCAT
A16: EziSERVO-EC | B16: AC 100~240V | C16: 3 | D16: - | E16: EtherCAT (CiA 402) | F16: 과열/과전류/위치오류 | G16: 폐루프 스텝 | H16: 폐루프(엔코더 내장)
A18: ※ 파스텍 DC 드라이버 전원: 별도 SMPS 필요 (DC 전원장치 용량 = 합계전류×1.25 이상) | 출처: Fastech 제품 카탈로그

Sheet 차단기 규격 참조표
A1: 차단기 규격 참조표 (MCCB / MCB 3P, AC 220V)
A3: 정격전류 (A) | B3: 적용 부하전류 범위 (A) | C3: 제조사 | D3: 모델 (3P) | E3: 비고
A4: 3 | B4: ~2.4A | C4: LS/Chint | D4: ABN3c / NXB-63 | E4: 조명, 소형 제어회로
A5: 5 | B5: 2.4~4A | C5: LS/Chint | D5: ABN5c / NXB-63 | E5: 소형 I/O, 팬
A6: 10 | B6: 4~8A | C6: LS/Chint | D6: ABN10c / NXB-63 | E6: 소형 서보 1~2축
A7: 15 | B7: 8~12A | C7: LS/Chint | D7: ABN15c / NXB-63 | E7: 판넬2 권장
A8: 20 | B8: 12~16A | C8: LS/Chint | D8: ABN20c / NXB-63 | E8: 판넬1/3/4 권장
A9: 25 | B9: 16~20A | C9: LS/Chint | D9: ABN25c / NXB-63
A10: 30 | B10: 20~24A | C10: LS/Chint | D10: ABN30c / NXB-63 | E10: 다축 서보 판넬
A11: 40 | B11: 24~32A | C11: LS/Chint | D11: ABN40c
A12: 50 | B12: 32~40A | C12: LS/Chint | D12: ABN50c
A13: 63 | B13: 40~50A | C13: LS/Chint | D13: ABN63c | E13: 대형 판넬
A14: 75 | B14: 50~60A | C14: LS/Chint | D14: ABN75c | E14: 메인 차단기 (판넬 합산)
