Workbook

Sheet 판넬별 차단기 선정표
A1: 대구텍 검사기 F2 #1 — 판넬별 전류·용량 계산 및 차단기 선정표
A2: 전원: | B2: AC 220V / 3상 | C2: 역률(PF): | D2: 0.95 | E2: 안전계수: | F2: 1.25 | G2: 수용률: | H2: 0.7 | I2: 작성일: | J2: 2026-04-03 | K2: ▶ 역률(PF): kVA 환산에 반영 ▶ 안전계수×1.25: 각 판넬 소계의 권장차단기 산출 ▶ 수용률: J열 설계전류 = 정격전류(E열)×수용률
A4: ▶ 전체 부하 요약 (판넬별 소계 완성 후 자동계산)
A5: 구분 | B5: 총 정격전류 (A) | C5: ×안전계수(1.25) | D5: 권장 차단기 (A) | E5: 총 부하 (kVA) | F5: 비고
A6: AC 3상 220V 파나소닉 A6 서보드라이버 | B6: =E34+E54+E78+E106 | C6: =B6*$F$2 | D6: → Sheet4 참조 | E6: =B6*220*SQRT(3)/1000 | F6: =TEXT(B6,"0.00")&"A × $F$2 = "&TEXT(C6,"0.00")&"A 이상 선정"
A7: AC 단상 220V 파스텍 EziServo/EziSpeed | B7: =E114 | C7: =B7*$F$2 | D7: → Sheet4 참조 | E7: =B7*220/1000 | F7: =TEXT(B7,"0.00")&"A × $F$2 = "&TEXT(C7,"0.00")&"A 이상 선정"
A8: DC 24V 서보I/O·센서·솔레노이드 등 | B8: =E131 | C8: =B8*$F$2 | D8: SMPS 별도 | E8: =B8*24/1000 | F8: DC 전원장치 용량: 합계전류 × 1.25 이상
A9: 기타 부하 UPS·HMI·조명 등 | B9: =E141 | C9: =B9*$F$2 | D9: → Sheet4 참조 | E9: =B9*220/1000 | F9: =TEXT(B9,"0.00")&"A × $F$2 = "&TEXT(C9,"0.00")&"A 이상 선정"
A11: ▶ R/S/T 상별 전류 편중 분석 (참조용 — 상 배분 최적화 시 활용)
A12: 구분 | B12: R상 (A) | C12: S상 (A) | D12: T상 (A) | E12: 최대-최소 (A) | F12: 불균형률 (%) | G12: 판정 | H12: 기준: 10% 이하 권장
A13: AC 3상 서보드라이버
A14: 기타 AC 부하
A15: 전체 합계
A17: 기준: | B17: 역률(PF)=$D$2 | C17: 안전계수=$F$2 | D17: 수용률=$H$2
A18: 판넬 | B18: 축/유닛명 | C18: 드라이버/장치 모델 | D18: 출력(W) [자동] | E18: 정격전류(A) [자동] | F18: 상수 | G18: R상 할당 | H18: S상 할당 | I18: T상 할당 | J18: 설계전류(A) =E×수용률 | K18: 전원 구분 | O18: 권장 차단기(A) | P18: 제조사/모델 | Q18: 비고 / 수식 설명
K19: AC 3상 220V | L19: AC 단상 220V | M19: DC 24V | N19: 기타
A20: ■ 판넬 1 — AC 3상 서보드라이버 (파나소닉 A6)
A21: 판넬1 | B21: LO_Y1 | C21: MDDLN55BL | D21: =IFERROR(VLOOKUP(C21,파나소닉A6규격!$A:$B,2,FALSE),"") | E21: =IFERROR(VLOOKUP(C21,파나소닉A6규격!$A:$C,3,FALSE),IFERROR(VLOOKUP(C21,파스텍EziServo규격!$A:$B,2,FALSE),"")) | F21: 1 | G21: 1 | H21: 1 | I21: 1 | J21: =IF(E21="","",ROUND(E21*$H$2,3)) | K21: ● | Q21: =IF(D21="","","출력:"&D21&"W 정격:"&TEXT(E21,"0.0")&"A 설계:"&TEXT(J21,"0.000")&"A")
A22: 판넬1 | B22: LO_X1 | C22: MCDLN35BL | D22: =IFERROR(VLOOKUP(C22,파나소닉A6규격!$A:$B,2,FALSE),"") | E22: =IFERROR(VLOOKUP(C22,파나소닉A6규격!$A:$C,3,FALSE),IFERROR(VLOOKUP(C22,파스텍EziServo규격!$A:$B,2,FALSE),"")) | F22: 1 | G22: 1 | H22: 1 | I22: 1 | J22: =IF(E22="","",ROUND(E22*$H$2,3)) | K22: ● | Q22: =IF(D22="","","출력:"&D22&"W 정격:"&TEXT(E22,"0.0")&"A 설계:"&TEXT(J22,"0.000")&"A")
A23: 판넬1 | B23: LO_Z1 | C23: MADLN05BE | D23: =IFERROR(VLOOKUP(C23,파나소닉A6규격!$A:$B,2,FALSE),"") | E23: =IFERROR(VLOOKUP(C23,파나소닉A6규격!$A:$C,3,FALSE),IFERROR(VLOOKUP(C23,파스텍EziServo규격!$A:$B,2,FALSE),"")) | F23: 1 | G23: 1 | H23: 1 | I23: 1 | J23: =IF(E23="","",ROUND(E23*$H$2,3)) | K23: ● | Q23: =IF(D23="","","출력:"&D23&"W 정격:"&TEXT(E23,"0.0")&"A 설계:"&TEXT(J23,"0.000")&"A")
A24: 판넬1 | B24: ULO_Y1 | C24: MCDLN35BL | D24: =IFERROR(VLOOKUP(C24,파나소닉A6규격!$A:$B,2,FALSE),"") | E24: =IFERROR(VLOOKUP(C24,파나소닉A6규격!$A:$C,3,FALSE),IFERROR(VLOOKUP(C24,파스텍EziServo규격!$A:$B,2,FALSE),"")) | F24: 1 | G24: 1 | H24: 1 | I24: 1 | J24: =IF(E24="","",ROUND(E24*$H$2,3)) | K24: ● | Q24: =IF(D24="","","출력:"&D24&"W 정격:"&TEXT(E24,"0.0")&"A 설계:"&TEXT(J24,"0.000")&"A")
A25: 판넬1 | B25: ULO_X1 | C25: MCDLN35BL | D25: =IFERROR(VLOOKUP(C25,파나소닉A6규격!$A:$B,2,FALSE),"") | E25: =IFERROR(VLOOKUP(C25,파나소닉A6규격!$A:$C,3,FALSE),IFERROR(VLOOKUP(C25,파스텍EziServo규격!$A:$B,2,FALSE),"")) | F25: 1 | G25: 1 | H25: 1 | I25: 1 | J25: =IF(E25="","",ROUND(E25*$H$2,3)) | K25: ● | Q25: =IF(D25="","","출력:"&D25&"W 정격:"&TEXT(E25,"0.0")&"A 설계:"&TEXT(J25,"0.000")&"A")
A26: 판넬1 | B26: ULO_Z1 | C26: MADLN05BE | D26: =IFERROR(VLOOKUP(C26,파나소닉A6규격!$A:$B,2,FALSE),"") | E26: =IFERROR(VLOOKUP(C26,파나소닉A6규격!$A:$C,3,FALSE),IFERROR(VLOOKUP(C26,파스텍EziServo규격!$A:$B,2,FALSE),"")) | F26: 1 | G26: 1 | H26: 1 | I26: 1 | J26: =IF(E26="","",ROUND(E26*$H$2,3)) | K26: ● | Q26: =IF(D26="","","출력:"&D26&"W 정격:"&TEXT(E26,"0.0")&"A 설계:"&TEXT(J26,"0.000")&"A")
A27: 판넬1 | B27: NG_EV | C27: MCDLN35BE | D27: =IFERROR(VLOOKUP(C27,파나소닉A6규격!$A:$B,2,FALSE),"") | E27: =IFERROR(VLOOKUP(C27,파나소닉A6규격!$A:$C,3,FALSE),IFERROR(VLOOKUP(C27,파스텍EziServo규격!$A:$B,2,FALSE),"")) | F27: 1 | G27: 1 | H27: 1 | I27: 1 | J27: =IF(E27="","",ROUND(E27*$H$2,3)) | K27: ● | Q27: =IF(D27="","","출력:"&D27&"W 정격:"&TEXT(E27,"0.0")&"A 설계:"&TEXT(J27,"0.000")&"A")
A28: 판넬1 | B28: NG_FD | C28: MADLN05BE | D28: =IFERROR(VLOOKUP(C28,파나소닉A6규격!$A:$B,2,FALSE),"") | E28: =IFERROR(VLOOKUP(C28,파나소닉A6규격!$A:$C,3,FALSE),IFERROR(VLOOKUP(C28,파스텍EziServo규격!$A:$B,2,FALSE),"")) | F28: 1 | G28: 1 | H28: 1 | I28: 1 | J28: =IF(E28="","",ROUND(E28*$H$2,3)) | K28: ● | Q28: =IF(D28="","","출력:"&D28&"W 정격:"&TEXT(E28,"0.0")&"A 설계:"&TEXT(J28,"0.000")&"A")
A29: 판넬1 | B29: NG_FD_Z | C29: MBDLN25BE | D29: =IFERROR(VLOOKUP(C29,파나소닉A6규격!$A:$B,2,FALSE),"") | E29: =IFERROR(VLOOKUP(C29,파나소닉A6규격!$A:$C,3,FALSE),IFERROR(VLOOKUP(C29,파스텍EziServo규격!$A:$B,2,FALSE),"")) | F29: 1 | G29: 1 | H29: 1 | I29: 1 | J29: =IF(E29="","",ROUND(E29*$H$2,3)) | K29: ● | Q29: =IF(D29="","","출력:"&D29&"W 정격:"&TEXT(E29,"0.0")&"A 설계:"&TEXT(J29,"0.000")&"A")
A30: 판넬1 | B30: NG_FD_ALIGN | C30: MADLN05BE | D30: =IFERROR(VLOOKUP(C30,파나소닉A6규격!$A:$B,2,FALSE),"") | E30: =IFERROR(VLOOKUP(C30,파나소닉A6규격!$A:$C,3,FALSE),IFERROR(VLOOKUP(C30,파스텍EziServo규격!$A:$B,2,FALSE),"")) | F30: 1 | G30: 1 | H30: 1 | I30: 1 | J30: =IF(E30="","",ROUND(E30*$H$2,3)) | K30: ● | Q30: =IF(D30="","","출력:"&D30&"W 정격:"&TEXT(E30,"0.0")&"A 설계:"&TEXT(J30,"0.000")&"A")
A31: 판넬1 | B31: NG_FD_INDEX | C31: MBDLN25BE | D31: =IFERROR(VLOOKUP(C31,파나소닉A6규격!$A:$B,2,FALSE),"") | E31: =IFERROR(VLOOKUP(C31,파나소닉A6규격!$A:$C,3,FALSE),IFERROR(VLOOKUP(C31,파스텍EziServo규격!$A:$B,2,FALSE),"")) | F31: 1 | G31: 1 | H31: 1 | I31: 1 | J31: =IF(E31="","",ROUND(E31*$H$2,3)) | K31: ● | Q31: =IF(D31="","","출력:"&D31&"W 정격:"&TEXT(E31,"0.0")&"A 설계:"&TEXT(J31,"0.000")&"A")
A32: 판넬1 | B32: JIG_ULO_Y | C32: MADLN05BE | D32: =IFERROR(VLOOKUP(C32,파나소닉A6규격!$A:$B,2,FALSE),"") | E32: =IFERROR(VLOOKUP(C32,파나소닉A6규격!$A:$C,3,FALSE),IFERROR(VLOOKUP(C32,파스텍EziServo규격!$A:$B,2,FALSE),"")) | F32: 1 | G32: 1 | H32: 1 | I32: 1 | J32: =IF(E32="","",ROUND(E32*$H$2,3)) | K32: ● | Q32: =IF(D32="","","출력:"&D32&"W 정격:"&TEXT(E32,"0.0")&"A 설계:"&TEXT(J32,"0.000")&"A")
A33: 판넬1 | B33: JIG_ULO_Z | C33: MADLN05BE | D33: =IFERROR(VLOOKUP(C33,파나소닉A6규격!$A:$B,2,FALSE),"") | E33: =IFERROR(VLOOKUP(C33,파나소닉A6규격!$A:$C,3,FALSE),IFERROR(VLOOKUP(C33,파스텍EziServo규격!$A:$B,2,FALSE),"")) | F33: 1 | G33: 1 | H33: 1 | I33: 1 | J33: =IF(E33="","",ROUND(E33*$H$2,3)) | K33: ● | Q33: =IF(D33="","","출력:"&D33&"W 정격:"&TEXT(E33,"0.0")&"A 설계:"&TEXT(J33,"0.000")&"A")
A34: ▶ 판넬 1 AC합계 | E34: =SUM(E21:E33) | J34: =SUM(J21:J33) | O34: 20 | P34: LS ABN20c | Q34: =TEXT(J34,"0.00")&"A×안전계수("&$F$2&")="&TEXT(J34*$F$2,"0.00")&"A → 20A 선정"
A35: 판넬 | B35: 축/유닛명 | C35: 드라이버/장치 모델 | D35: 출력W[자동] | E35: 정격전류[자동] | F35: 상수 | G35: R상 | H35: S상 | I35: T상 | J35: 설계전류(×수용률) | K35: AC3상 | L35: AC단상 | M35: DC24V | N35: 기타 | O35: 권장차단기 | P35: 제조사/모델 | Q35: 비고
A36: ■ 파스텍 EziServo / EziSpeed (AC 단상 입력) — 판넬 1
A37: 판넬1 | B37: LO_R1_1 | C37: Ezi-EC-42XL-A | D37: =IFERROR(VLOOKUP(C37,파나소닉A6규격!$A:$B,2,FALSE),"") | E37: =IFERROR(VLOOKUP(C37,파나소닉A6규격!$A:$C,3,FALSE),IFERROR(VLOOKUP(C37,파스텍EziServo규격!$A:$B,2,FALSE),"")) | F37: 1 | G37: 0 | H37: 0 | I37: 0 | J37: =IF(E37="","",ROUND(E37*$H$2,3)) | L37: ● | Q37: LO 회전 R1 #1
A38: 판넬1 | B38: LO_R1_2 | C38: Ezi-EC-42XL-A | D38: =IFERROR(VLOOKUP(C38,파나소닉A6규격!$A:$B,2,FALSE),"") | E38: =IFERROR(VLOOKUP(C38,파나소닉A6규격!$A:$C,3,FALSE),IFERROR(VLOOKUP(C38,파스텍EziServo규격!$A:$B,2,FALSE),"")) | F38: 1 | G38: 0 | H38: 0 | I38: 0 | J38: =IF(E38="","",ROUND(E38*$H$2,3)) | L38: ● | Q38: LO 회전 R1 #2
A39: 판넬 | B39: 축/유닛명 | C39: 드라이버/장치 모델 | D39: 출력W[자동] | E39: 정격전류[자동] | F39: 상수 | G39: R상 | H39: S상 | I39: T상 | J39: 설계전류(×수용률) | K39: AC3상 | L39: AC단상 | M39: DC24V | N39: 기타 | O39: 권장차단기 | P39: 제조사/모델 | Q39: 비고
A40: ■ 판넬 2 — AC 3상 서보드라이버 (파나소닉 A6)
A41: 판넬2 | B41: GOOD_EV | C41: MCDLN35BE | D41: =IFERROR(VLOOKUP(C41,파나소닉A6규격!$A:$B,2,FALSE),"") | E41: =IFERROR(VLOOKUP(C41,파나소닉A6규격!$A:$C,3,FALSE),IFERROR(VLOOKUP(C41,파스텍EziServo규격!$A:$B,2,FALSE),"")) | F41: 1 | G41: 1 | H41: 1 | I41: 1 | J41: =IF(E41="","",ROUND(E41*$H$2,3)) | K41: ●
A42: 판넬2 | B42: GOOD_FD | C42: MADLN05BE | D42: =IFERROR(VLOOKUP(C42,파나소닉A6규격!$A:$B,2,FALSE),"") | E42: =IFERROR(VLOOKUP(C42,파나소닉A6규격!$A:$C,3,FALSE),IFERROR(VLOOKUP(C42,파스텍EziServo규격!$A:$B,2,FALSE),"")) | F42: 1 | G42: 1 | H42: 1 | I42: 1 | J42: =IF(E42="","",ROUND(E42*$H$2,3)) | K42: ●
A43: 판넬2 | B43: GOOD_FD_Z | C43: MBDLN25BE | D43: =IFERROR(VLOOKUP(C43,파나소닉A6규격!$A:$B,2,FALSE),"") | E43: =IFERROR(VLOOKUP(C43,파나소닉A6규격!$A:$C,3,FALSE),IFERROR(VLOOKUP(C43,파스텍EziServo규격!$A:$B,2,FALSE),"")) | F43: 1 | G43: 1 | H43: 1 | I43: 1 | J43: =IF(E43="","",ROUND(E43*$H$2,3)) | K43: ●
...

Sheet 파나소닉A6규격
A1: 파나소닉 A6 서보드라이버 정격입력전류 (카탈로그 기준, 3상 AC200V)
A2: 드라이버 모델 | B2: 정격출력 (W) | C2: 정격입력전류 (A) | D2: 비고
A3: MADLN05BE | B3: 50 | C3: 0.3 | D3: 50W 서보드라이버
A4: MADLN10BE | B4: 100 | C4: 0.5 | D4: 100W 서보드라이버
A5: MADLN15BE | B5: 200 | C5: 1 | D5: 200W 서보드라이버
A6: MBDLN25BE | B6: 400 | C6: 1.5 | D6: 400W 서보드라이버
A7: MCDLN35BL | B7: 750 | C7: 2.4 | D7: 750W 서보드라이버 (BL)
A8: MCDLN35BE | B8: 750 | C8: 2.4 | D8: 750W 서보드라이버 (BE)
A9: MDDLN55BL | B9: 1000 | C9: 3.4 | D9: 1kW 서보드라이버 (BL)
A10: MDDLN55BE | B10: 1000 | C10: 3.4 | D10: 1kW 서보드라이버 (BE)
A11: MDDLN85BL | B11: 1500 | C11: 5.5 | D11: 1.5kW 서보드라이버 (BL)
A13: ※ A열 모델명과 메인시트 C열 코드 정확히 일치 필요 | 카탈로그 정격입력전류 기준 | 모델 추가 시 이 시트에 행 추가
A15: 파나소닉 A6 서보드라이버 규격표 (MINAS A6 Series)
A16: 드라이버 모델 | B16: 대응 모터 | C16: 정격출력(W) | D16: 전원 | E16: 정격입력전류(A) | F16: 최대입력전류(A) | G16: 제어방식 | H16: 통신 | I16: 특이사항 | J16: 비고
A17: MADLN05BE | B17: MSMF/MQMF 50W | C17: 50 | D17: AC3상 200V | E17: 0.3 | F17: 0.8 | G17: Full-Closed | H17: EtherCAT/Modbus | I17: 소형 단축용
A18: MADLN10BE | B18: MSMF/MQMF 100W | C18: 100 | D18: AC3상 200V | E18: 0.5 | F18: 1.2 | G18: Full-Closed | H18: EtherCAT/Modbus
A19: MADLN15BE | B19: MSMF/MQMF 200W | C19: 200 | D19: AC3상 200V | E19: 1 | F19: 2.4 | G19: Full-Closed | H19: EtherCAT/Modbus
A20: MBDLN25BE | B20: MSMF/MQMF 400W | C20: 400 | D20: AC3상 200V | E20: 1.5 | F20: 4 | G20: Full-Closed | H20: EtherCAT/Modbus
A21: MCDLN35BL | B21: MSMF/MQMF 750W | C21: 750 | D21: AC3상 200V | E21: 2.4 | F21: 7 | G21: Full-Closed | H21: EtherCAT/Modbus | I21: 중형 축용
A22: MCDLN35BE | B22: MSMF/MQMF 750W | C22: 750 | D22: AC3상 200V | E22: 2.4 | F22: 7 | G22: Full-Closed | H22: EtherCAT/Modbus | I22: Brake 내장형
A23: MDDLN55BL | B23: MSMF 1kW | C23: 1000 | D23: AC3상 200V | E23: 3.4 | F23: 10 | G23: Full-Closed | H23: EtherCAT/Modbus | I23: 대형 주축용
A24: MDDLN85BL | B24: MSMF 1.5kW | C24: 1500 | D24: AC3상 200V | E24: 5.5 | F24: 15 | G24: Full-Closed | H24: EtherCAT/Modbus
A25: MEDLN15BL | B25: MSMF 2kW | C25: 2000 | D25: AC3상 200V | E25: 7.5 | F25: 20 | G25: Full-Closed | H25: EtherCAT/Modbus
A26: MFDLN23BL | B26: MSMF 3kW | C26: 3000 | D26: AC3상 200V | E26: 11 | F26: 30 | G26: Full-Closed | H26: EtherCAT/Modbus | I26: 고출력
A27: ※ 정격입력전류: I = P_출력(VA) ÷ (√3 × V_입력 × PF) | 안전계수 1.25 적용 후 차단기 선정 | 출처: Panasonic MINAS A6 Catalog

Sheet 파스텍EziServo규격
A1: 파스텍 EZS2/EziServo 정격전류 (VLOOKUP 소스)
A2: 드라이버 모델 | B2: 정격전류 (A) | C2: 비고
A3: EZS2-EC-42M | B3: 1.2 | C3: DC 24V 입력 스텝서보
A4: EZS2-EC-42XL | B4: 1.2 | C4: DC 24V 입력 스텝서보 (XL)
A5: Ezi-EC-42M-A | B5: 1.5 | C5: AC 입력 스텝서보
A6: Ezi-EC-42XL-A | B6: 2 | C6: AC 입력 스텝서보 (XL)
A7: EZI-SPEED60H30CR100P | B7: 1 | C7: DC 24V 입력 스텝모터드라이버

Sheet 차단기 규격 참조표
A1: 차단기 규격 참조표 (MCCB / MCB 3P, AC 220V)
A3: 정격전류 (A) | B3: 적용 부하전류 범위 (A) | C3: 제조사 | D3: 모델 (3P) | E3: 비고
A4: 3 | B4: ~2.4A | C4: LS/Chint | D4: ABN3c / NXB-63 | E4: 조명, 소형 제어회로
A5: 5 | B5: 2.4~4A | C5: LS/Chint | D5: ABN5c / NXB-63 | E5: 소형 I/O, 팬
A6: 10 | B6: 4~8A | C6: LS/Chint | D6: ABN10c / NXB-63 | E6: 소형 서보 1~2축
A7: 15 | B7: 8~12A | C7: LS/Chint | D7: ABN15c / NXB-63 | E7: 판넬2 권장
A8: 20 | B8: 12~16A | C8: LS/Chint | D8: ABN20c / NXB-63 | E8: 판넬1/3/4 권장
A9: 25 | B9: 16~20A | C9: LS/Chint | D9: ABN25c / NXB-63
A10: 30 | B10: 20~24A | C10: LS/Chint | D10: ABN30c / NXB-63 | E10: 다축 서보 판넬
A11: 40 | B11: 24~32A | C11: LS/Chint | D11: ABN40c
A12: 50 | B12: 32~40A | C12: LS/Chint | D12: ABN50c
A13: 63 | B13: 40~50A | C13: LS/Chint | D13: ABN63c | E13: 대형 판넬
A14: 75 | B14: 50~60A | C14: LS/Chint | D14: ABN75c | E14: 메인 차단기 (판넬 합산)
A15: 100 | B15: 60~80A | C15: LS/Chint | D15: ABN100c
