Workbook

Sheet 전류·용량 계산표
A1: 대구텍 검사기 F2 #1 — 판넬별 전류용량 계산 및 차단기 선정표
A2: ▶ 전체 부하 요약 (상단 자동계산 — 하단 합계행 수식 연동)
A3: 구분 | B3: 총 정격전류(A) | C3: 안전계수×1.25 | D3: 권장 차단기(A) | E3: 비고
A4: AC 서보드라이버 (파나소닉 A6) | B4: (자동) | C4: (자동) | D4: (자동) | E4: (자동)
A5: DC24V EziServo/EziSpeed | B5: (자동) | C5: (자동) | D5: (자동) | E5: (자동)
A6: DC 24V 공통 부하 (I/O·센서 등) | B6: (자동) | C6: (자동) | D6: (자동) | E6: (자동)
A7: 기타 (HMI·조명·PC 등) | B7: (자동) | C7: (자동) | D7: (자동) | E7: (자동)
A9: ▶ R/S/T 상별 전류 편중 분석 (AC 서보드라이버 기준)
B10: R상(A) | C10: S상(A) | D10: T상(A) | E10: 최대-최소(A) | F10: 불균형률(%) | G10: 판정 | H10: 기준: 불균형률 10% 이하 권장
A11: AC 서보드라이버 합계
A12: 판넬1
A13: 판넬2
A14: 판넬3
A15: 판넬4
A17: 판넬 | B17: Axis Name | C17: 드라이버 모델 (직접 입력) | D17: 출력(W) [자동] | E17: 정격전류(A) [자동] | F17: 상수 | G17: R상 | H17: S상 | I17: T상 | J17: 운전전류(A) | K17: 전원 구분 | O17: 차단기 선정(A) | P17: 제조사/모델 | Q17: 비고/수식설명
K18: AC 서보 (파나소닉) | L18: DC 24V (EziServo) | M18: DC 24V (공통) | N18: 기타
A19: ■ 판넬1 — 파나소닉 A6 서보드라이버 (AC200V)
A20: 판넬1 | B20: LO_Y1 | C20: MDDLN55BL | D20: =IFERROR(VLOOKUP(C20,파나소닉A6규격!$A:$C,2,FALSE),IFERROR(VLOOKUP(C20,파스텍EziServo규격!$A:$C,1,FALSE),"")) | E20: =IFERROR(VLOOKUP(C20,파나소닉A6규격!$A:$C,3,FALSE),IFERROR(VLOOKUP(C20,파스텍EziServo규격!$A:$C,3,FALSE),"")) | F20: 3 | G20: 1 | H20: 1 | I20: 1 | J20: =IFERROR(E20*0.9,"") | K20: ● | Q20: Linear Motor Driver (AC200V)
B21: LO_X1 | C21: MCDLN35BL | D21: =IFERROR(VLOOKUP(C21,파나소닉A6규격!$A:$C,2,FALSE),IFERROR(VLOOKUP(C21,파스텍EziServo규격!$A:$C,1,FALSE),"")) | E21: =IFERROR(VLOOKUP(C21,파나소닉A6규격!$A:$C,3,FALSE),IFERROR(VLOOKUP(C21,파스텍EziServo규격!$A:$C,3,FALSE),"")) | F21: 3 | G21: 0 | H21: 1 | I21: 1 | J21: =IFERROR(E21*0.9,"") | K21: ● | Q21: Linear Motor Driver (AC200V)
B22: LO_Z1 | C22: MADLN05BE | D22: =IFERROR(VLOOKUP(C22,파나소닉A6규격!$A:$C,2,FALSE),IFERROR(VLOOKUP(C22,파스텍EziServo규격!$A:$C,1,FALSE),"")) | E22: =IFERROR(VLOOKUP(C22,파나소닉A6규격!$A:$C,3,FALSE),IFERROR(VLOOKUP(C22,파스텍EziServo규격!$A:$C,3,FALSE),"")) | F22: 1 | G22: 1 | H22: 0 | I22: 0 | J22: =IFERROR(E22*0.9,"") | K22: ● | Q22: I=VA/(220×PF=0.85)
B23: ULO_Y1 | C23: MCDLN35BL | D23: =IFERROR(VLOOKUP(C23,파나소닉A6규격!$A:$C,2,FALSE),IFERROR(VLOOKUP(C23,파스텍EziServo규격!$A:$C,1,FALSE),"")) | E23: =IFERROR(VLOOKUP(C23,파나소닉A6규격!$A:$C,3,FALSE),IFERROR(VLOOKUP(C23,파스텍EziServo규격!$A:$C,3,FALSE),"")) | F23: 3 | G23: 1 | H23: 1 | I23: 0 | J23: =IFERROR(E23*0.9,"") | K23: ● | Q23: Linear Motor Driver
B24: ULO_X1 | C24: MCDLN35BL | D24: =IFERROR(VLOOKUP(C24,파나소닉A6규격!$A:$C,2,FALSE),IFERROR(VLOOKUP(C24,파스텍EziServo규격!$A:$C,1,FALSE),"")) | E24: =IFERROR(VLOOKUP(C24,파나소닉A6규격!$A:$C,3,FALSE),IFERROR(VLOOKUP(C24,파스텍EziServo규격!$A:$C,3,FALSE),"")) | F24: 3 | G24: 0 | H24: 1 | I24: 1 | J24: =IFERROR(E24*0.9,"") | K24: ● | Q24: Linear Motor Driver
B25: ULO_Z1 | C25: MADLN05BE | D25: =IFERROR(VLOOKUP(C25,파나소닉A6규격!$A:$C,2,FALSE),IFERROR(VLOOKUP(C25,파스텍EziServo규격!$A:$C,1,FALSE),"")) | E25: =IFERROR(VLOOKUP(C25,파나소닉A6규격!$A:$C,3,FALSE),IFERROR(VLOOKUP(C25,파스텍EziServo규격!$A:$C,3,FALSE),"")) | F25: 1 | G25: 0 | H25: 0 | I25: 1 | J25: =IFERROR(E25*0.9,"") | K25: ●
B26: NG_EV | C26: MCDLN35BE | D26: =IFERROR(VLOOKUP(C26,파나소닉A6규격!$A:$C,2,FALSE),IFERROR(VLOOKUP(C26,파스텍EziServo규격!$A:$C,1,FALSE),"")) | E26: =IFERROR(VLOOKUP(C26,파나소닉A6규격!$A:$C,3,FALSE),IFERROR(VLOOKUP(C26,파스텍EziServo규격!$A:$C,3,FALSE),"")) | F26: 1 | G26: 1 | H26: 0 | I26: 0 | J26: =IFERROR(E26*0.9,"") | K26: ● | Q26: 800W 서보 (단상)
B27: NG_FD | C27: MADLN05BE | D27: =IFERROR(VLOOKUP(C27,파나소닉A6규격!$A:$C,2,FALSE),IFERROR(VLOOKUP(C27,파스텍EziServo규격!$A:$C,1,FALSE),"")) | E27: =IFERROR(VLOOKUP(C27,파나소닉A6규격!$A:$C,3,FALSE),IFERROR(VLOOKUP(C27,파스텍EziServo규격!$A:$C,3,FALSE),"")) | F27: 1 | G27: 0 | H27: 1 | I27: 0 | J27: =IFERROR(E27*0.9,"") | K27: ●
B28: NG_FD_Z | C28: MBDLN25BE | D28: =IFERROR(VLOOKUP(C28,파나소닉A6규격!$A:$C,2,FALSE),IFERROR(VLOOKUP(C28,파스텍EziServo규격!$A:$C,1,FALSE),"")) | E28: =IFERROR(VLOOKUP(C28,파나소닉A6규격!$A:$C,3,FALSE),IFERROR(VLOOKUP(C28,파스텍EziServo규격!$A:$C,3,FALSE),"")) | F28: 1 | G28: 1 | H28: 0 | I28: 0 | J28: =IFERROR(E28*0.9,"") | K28: ●
B29: NG_FD_ALIGN | C29: MADLN05BE | D29: =IFERROR(VLOOKUP(C29,파나소닉A6규격!$A:$C,2,FALSE),IFERROR(VLOOKUP(C29,파스텍EziServo규격!$A:$C,1,FALSE),"")) | E29: =IFERROR(VLOOKUP(C29,파나소닉A6규격!$A:$C,3,FALSE),IFERROR(VLOOKUP(C29,파스텍EziServo규격!$A:$C,3,FALSE),"")) | F29: 1 | G29: 0 | H29: 0 | I29: 1 | J29: =IFERROR(E29*0.9,"") | K29: ●
B30: NG_FD_INDEX | C30: MBDLN25BE | D30: =IFERROR(VLOOKUP(C30,파나소닉A6규격!$A:$C,2,FALSE),IFERROR(VLOOKUP(C30,파스텍EziServo규격!$A:$C,1,FALSE),"")) | E30: =IFERROR(VLOOKUP(C30,파나소닉A6규격!$A:$C,3,FALSE),IFERROR(VLOOKUP(C30,파스텍EziServo규격!$A:$C,3,FALSE),"")) | F30: 1 | G30: 1 | H30: 0 | I30: 0 | J30: =IFERROR(E30*0.9,"") | K30: ●
B31: JIG_ULO_Y | C31: MADLN05BE | D31: =IFERROR(VLOOKUP(C31,파나소닉A6규격!$A:$C,2,FALSE),IFERROR(VLOOKUP(C31,파스텍EziServo규격!$A:$C,1,FALSE),"")) | E31: =IFERROR(VLOOKUP(C31,파나소닉A6규격!$A:$C,3,FALSE),IFERROR(VLOOKUP(C31,파스텍EziServo규격!$A:$C,3,FALSE),"")) | F31: 1 | G31: 0 | H31: 1 | I31: 0 | J31: =IFERROR(E31*0.9,"") | K31: ●
B32: JIG_ULO_Z | C32: MADLN05BE | D32: =IFERROR(VLOOKUP(C32,파나소닉A6규격!$A:$C,2,FALSE),IFERROR(VLOOKUP(C32,파스텍EziServo규격!$A:$C,1,FALSE),"")) | E32: =IFERROR(VLOOKUP(C32,파나소닉A6규격!$A:$C,3,FALSE),IFERROR(VLOOKUP(C32,파스텍EziServo규격!$A:$C,3,FALSE),"")) | F32: 1 | G32: 0 | H32: 0 | I32: 1 | J32: =IFERROR(E32*0.9,"") | K32: ●
A33: 판넬1 AC 소계 소계 | E33: =SUM(E20:E32) | J33: =SUM(J20:J32) | O33: =CEILING(E33*1.25,5) | Q33: E×1.25→CEILING 5A 단위
A35: ■ 판넬1 — EziServo/EziSpeed (DC 24V)
B36: LO_R1 (#1) | C36: Ezi-EC-42XL-A | D36: =IFERROR(VLOOKUP(C36,파나소닉A6규격!$A:$C,2,FALSE),IFERROR(VLOOKUP(C36,파스텍EziServo규격!$A:$C,1,FALSE),"")) | E36: =IFERROR(VLOOKUP(C36,파나소닉A6규격!$A:$C,3,FALSE),IFERROR(VLOOKUP(C36,파스텍EziServo규격!$A:$C,3,FALSE),"")) | F36: 1 | G36: 0 | H36: 0 | I36: 0 | J36: =IFERROR(E36*0.9,"") | L36: ● | Q36: EziServo EC (DC24V)
B37: LO_R1 (#2) | C37: Ezi-EC-42XL-A | D37: =IFERROR(VLOOKUP(C37,파나소닉A6규격!$A:$C,2,FALSE),IFERROR(VLOOKUP(C37,파스텍EziServo규격!$A:$C,1,FALSE),"")) | E37: =IFERROR(VLOOKUP(C37,파나소닉A6규격!$A:$C,3,FALSE),IFERROR(VLOOKUP(C37,파스텍EziServo규격!$A:$C,3,FALSE),"")) | F37: 1 | G37: 0 | H37: 0 | I37: 0 | J37: =IFERROR(E37*0.9,"") | L37: ● | Q37: EziServo EC (DC24V)
A38: 판넬1 EziServo 소계 소계 | E38: =SUM(E36:E37) | J38: =SUM(J36:J37) | O38: =CEILING(E38*1.25,5) | Q38: E×1.25→CEILING 5A 단위
A40: ■ 판넬2 — 파나소닉 A6 서보드라이버 (AC200V)
A41: 판넬2 | B41: GOOD_EV | C41: MCDLN35BE | D41: =IFERROR(VLOOKUP(C41,파나소닉A6규격!$A:$C,2,FALSE),IFERROR(VLOOKUP(C41,파스텍EziServo규격!$A:$C,1,FALSE),"")) | E41: =IFERROR(VLOOKUP(C41,파나소닉A6규격!$A:$C,3,FALSE),IFERROR(VLOOKUP(C41,파스텍EziServo규격!$A:$C,3,FALSE),"")) | F41: 1 | G41: 1 | H41: 0 | I41: 0 | J41: =IFERROR(E41*0.9,"") | K41: ● | Q41: 800W 서보
B42: GOOD_FD | C42: MADLN05BE | D42: =IFERROR(VLOOKUP(C42,파나소닉A6규격!$A:$C,2,FALSE),IFERROR(VLOOKUP(C42,파스텍EziServo규격!$A:$C,1,FALSE),"")) | E42: =IFERROR(VLOOKUP(C42,파나소닉A6규격!$A:$C,3,FALSE),IFERROR(VLOOKUP(C42,파스텍EziServo규격!$A:$C,3,FALSE),"")) | F42: 1 | G42: 0 | H42: 1 | I42: 0 | J42: =IFERROR(E42*0.9,"") | K42: ●
B43: GOOD_FD_Z | C43: MBDLN25BE | D43: =IFERROR(VLOOKUP(C43,파나소닉A6규격!$A:$C,2,FALSE),IFERROR(VLOOKUP(C43,파스텍EziServo규격!$A:$C,1,FALSE),"")) | E43: =IFERROR(VLOOKUP(C43,파나소닉A6규격!$A:$C,3,FALSE),IFERROR(VLOOKUP(C43,파스텍EziServo규격!$A:$C,3,FALSE),"")) | F43: 1 | G43: 1 | H43: 0 | I43: 0 | J43: =IFERROR(E43*0.9,"") | K43: ●
B44: GOOD_FD_ALIGN | C44: MADLN05BE | D44: =IFERROR(VLOOKUP(C44,파나소닉A6규격!$A:$C,2,FALSE),IFERROR(VLOOKUP(C44,파스텍EziServo규격!$A:$C,1,FALSE),"")) | E44: =IFERROR(VLOOKUP(C44,파나소닉A6규격!$A:$C,3,FALSE),IFERROR(VLOOKUP(C44,파스텍EziServo규격!$A:$C,3,FALSE),"")) | F44: 1 | G44: 0 | H44: 0 | I44: 1 | J44: =IFERROR(E44*0.9,"") | K44: ●
...

Sheet 파나소닉A6규격
A1: 파나소닉 A6 드라이버 규격 (VLOOKUP 참조)
A3: 드라이버 모델 | B3: 정격출력(W) | C3: 정격입력전류(A) | D3: 비고
A4: MADLN05BE | B4: 100 | C4: 0.9 | D4: 50W~100W 서보
A5: MADLN10BE | B5: 100 | C5: 1.2 | D5: 100W 서보
A6: MADLN15BE | B6: 200 | C6: 1.5 | D6: 200W 서보
A7: MADLN23BE | B7: 400 | C7: 2.3 | D7: 400W 서보
A8: MBDLN25BE | B8: 400 | C8: 2.5 | D8: 400W 서보
A9: MBDLN55BE | B9: 750 | C9: 5 | D9: 750W 서보
A10: MCDLN35BE | B10: 800 | C10: 5 | D10: 750W~800W 서보
A11: MCDLN35BL | B11: 0 | C11: 5 | D11: Linear Motor Driver
A12: MDDLN55BL | B12: 0 | C12: 8.5 | D12: Linear Motor Driver (대형)

Sheet 파스텍EziServo규격
A1: 파스텍 EziServo / EziSpeed 규격 (VLOOKUP 참조)
A3: 드라이버/액추에이터 모델 | B3: 전원 | C3: 정격전류(A) | D3: 비고
A4: Ezi-EC-42XL-A | B4: DC 24V | C4: 2 | D4: EziServo EC 소형
A5: Ezi-EC-42M-A | B5: DC 24V | C5: 1.5 | D5: EziServo EC 미니
A6: EZI-SPEED60H30CR100P | B6: DC 24V | C6: 3 | D6: EziSpeed 컨베이어
A7: EM542S | B7: DC 24~50V | C7: 4.2 | D7: 파스텍 스텝드라이버
A8: EM806 | B8: DC 24~80V | C8: 8 | D8: 파스텍 스텝드라이버

Sheet 차단기규격
A1: 차단기 규격 참조표 (MCCB/MCB 3P, AC200V)
A3: 정격(A) | B3: 적용 전류범위 | C3: 제조사 | D3: 모델명 | E3: 비고
A4: 5 | B4: ~4A | C4: LS/Chint | D4: ABN5c / NXB-63 | E4: EziServo 2~3개
A5: 10 | B5: 4~8A | C5: LS/Chint | D5: ABN10c / NXB-63 | E5: 100W 서보 5축 이하
A6: 15 | B6: 8~12A | C6: LS/Chint | D6: ABN15c / NXB-63
A7: 20 | B7: 12~16A | C7: LS/Chint | D7: ABN20c / NXB-63 | E7: 중형 판넬
A8: 25 | B8: 16~20A | C8: LS/Chint | D8: ABN25c / NXB-63
A9: 30 | B9: 20~24A | C9: LS/Chint | D9: ABN30c / NXB-63 | E9: 다축 서보
A10: 40 | B10: 24~32A | C10: LS/Chint | D10: ABN40c
A11: 50 | B11: 32~40A | C11: LS/Chint | D11: ABN50c | E11: 대형 판넬
A12: 63 | B12: 40~50A | C12: LS/Chint | D12: ABN63c
A13: 75 | B13: 50~60A | C13: LS/Chint | D13: ABN75c | E13: 메인 차단기
A14: 100 | B14: 60~80A | C14: LS/Chint | D14: ABN100c
